Workbook

Sheet Assumptions
A1: Kar: financial model assumptions
A2: Legend: blue = input you can change · black = formula · green = pulled from another sheet · yellow = key assumption
A3: Active scenario | B3: Base
A4: Trips multiplier | B4: =INDEX(Scenarios!$B$5:$B$7,MATCH($B$3,Scenarios!$A$5:$A$7,0))
A5: Pro operators multiplier | B5: =INDEX(Scenarios!$C$5:$C$7,MATCH($B$3,Scenarios!$A$5:$A$7,0))
A6: Hardware multiplier | B6: =INDEX(Scenarios!$D$5:$D$7,MATCH($B$3,Scenarios!$A$5:$A$7,0))
A7: Lean fixed costs (1 = yes) | B7: =INDEX(Scenarios!$E$5:$E$7,MATCH($B$3,Scenarios!$A$5:$A$7,0))
A8: Register Sdn Bhd (1 = yes) | B8: =INDEX(Scenarios!$F$5:$F$7,MATCH($B$3,Scenarios!$A$5:$A$7,0))
A10: Pricing and per-trip economics
A11: Average trip price (RM) | B11: 80 | C11: Mix of 4h (~RM36), day (~RM75) and 2-3 day home trips (~RM150-210). Kar estimate; replace with real average after 50 trips.
A12: Customer booking fee (% of trip) | B12: 0.05 | C12: Set in the app (platform_settings.customer_fee_rate).
A13: Minimum booking fee (RM) | B13: 3 | C13: So short trips do not lose money after gateway fees.
A14: Pro commission on Kar-brought app bookings (%) | B14: 0.05 | C14: Price not final. 0% on the operator's own WhatsApp bookings.
A15: Commission starts in month | B15: 4 | C15: Months 1-3 are the pilot (commission waived).
A16: Small fees Kar keeps per trip (RM) | B16: 1.4 | C16: Late-fee share RM0.50 + claim handling (3 per 100 trips x RM30) RM0.90.
A17: Payment gateway cost per trip (RM) | B17: 2 | C17: Billplz FPX ~RM1-1.50 per bill, plus a buffer.
A18: Goodwill / bad-debt reserve (% of trip) | B18: 0.01 | C18: Credits and unrecoverable amounts.
A19: Pro subscription (RM/month per operator) | B19: 149 | C19: Price not final; test RM99-199 in operator interviews.
A20: Key box profit per unit (RM) | B20: 150 | C20: Sold installed at ~RM299, costs ~RM149.
A21: GPS tracker profit per unit (RM) | B21: 150 | C21: From month 7.
A22: GPS tracker subscription profit (RM/month per tracker) | B22: 10 | C22: Data SIM resale margin.
A24: One-off costs
A25: Lawyer-checked terms, house rules, privacy policy | B25: 2000
A26: Apple developer account (USD 99/yr) | B26: 450
A27: Google Play account (one-time) | B27: 110
A28: SSM renewal and adding the business activity | B28: 100
A29: Launch marketing (posters, campus booth) | B29: 800
A30: First 5 key boxes (earned back as they sell) | B30: 750
A31: Starting claims reserve | B31: 1000
A32: Total start-up costs (month 0) | B32: =SUM(B25:B31)
A33: Sdn Bhd registration (RM) | B33: 1500
A34: Register Sdn Bhd in month | B34: 7
A36: Monthly drivers (Base case, before scenario multipliers)
A37: Driver | B37: M1 | C37: M2 | D37: M3 | E37: M4 | F37: M5 | G37: M6 | H37: M7 | I37: M8 | J37: M9 | K37: M10 | L37: M11 | M37: M12
A38: App trips | B38: 40 | C38: 80 | D38: 130 | E38: 180 | F38: 230 | G38: 280 | H38: 330 | I38: 380 | J38: 420 | K38: 460 | L38: 500 | M38: 540
A39: Paying Pro operators | B39: 0 | C39: 3 | D39: 5 | E39: 6 | F39: 7 | G39: 8 | H39: 10 | I39: 11 | J39: 12 | K39: 13 | L39: 14 | M39: 15
A40: Key boxes sold | B40: 0 | C40: 2 | D40: 3 | E40: 3 | F40: 3 | G40: 3 | H40: 4 | I40: 4 | J40: 4 | K40: 4 | L40: 4 | M40: 4
A41: GPS trackers sold | B41: 0 | C41: 0 | D41: 0 | E41: 0 | F41: 0 | G41: 0 | H41: 2 | I41: 2 | J41: 2 | K41: 2 | L41: 2 | M41: 2
A42: Fixed costs, normal (RM) | B42: 900 | C42: 900 | D42: 900 | E42: 1800 | F42: 1800 | G42: 1800 | H42: 3450 | I42: 3450 | J42: 3450 | K42: 3450 | L42: 3450 | M42: 3450
A43: Fixed costs, lean (RM) | B43: 900 | C43: 900 | D43: 900 | E43: 900 | F43: 900 | G43: 900 | H43: 1800 | I43: 1800 | J43: 1800 | K43: 1800 | L43: 1800 | M43: 1800
...

Sheet Cash Flow
A1: Monthly cash flow (RM)
A2: ="Scenario: "&Assumptions!B3
A3: Line | B3: Month 0 | C3: Month 1 | D3: Month 2 | E3: Month 3 | F3: Month 4 | G3: Month 5 | H3: Month 6 | I3: Month 7 | J3: Month 8 | K3: Month 9 | L3: Month 10 | M3: Month 11 | N3: Month 12 | O3: Year 1
A4: Month | B4: 0 | C4: 1 | D4: 2 | E4: 3 | F4: 4 | G4: 5 | H4: 6 | I4: 7 | J4: 8 | K4: 9 | L4: 10 | M4: 11 | N4: 12
A5: App trips | C5: =Assumptions!B$38*Assumptions!$B$4 | D5: =Assumptions!C$38*Assumptions!$B$4 | E5: =Assumptions!D$38*Assumptions!$B$4 | F5: =Assumptions!E$38*Assumptions!$B$4 | G5: =Assumptions!F$38*Assumptions!$B$4 | H5: =Assumptions!G$38*Assumptions!$B$4 | I5: =Assumptions!H$38*Assumptions!$B$4 | J5: =Assumptions!I$38*Assumptions!$B$4 | ... N5: =Assumptions!M$38*Assumptions!$B$4 | O5: =SUM(B5:N5)
A6: Booking fee per trip | C6: =MAX(Assumptions!$B$11*Assumptions!$B$12,Assumptions!$B$13) | D6: =MAX(Assumptions!$B$11*Assumptions!$B$12,Assumptions!$B$13) | E6: =MAX(Assumptions!$B$11*Assumptions!$B$12,Assumptions!$B$13) | F6: =MAX(Assumptions!$B$11*Assumptions!$B$12,Assumptions!$B$13) | G6: =MAX(Assumptions!$B$11*Assumptions!$B$12,Assumptions!$B$13) | H6: =MAX(Assumptions!$B$11*Assumptions!$B$12,Assumptions!$B$13) | I6: =MAX(Assumptions!$B$11*Assumptions!$B$12,Assumptions!$B$13) | J6: =MAX(Assumptions!$B$11*Assumptions!$B$12,Assumptions!$B$13) | ... N6: =MAX(Assumptions!$B$11*Assumptions!$B$12,Assumptions!$B$13)
A7: Commission per trip | C7: =IF(C$4>=Assumptions!$B$15,Assumptions!$B$11*Assumptions!$B$14,0) | D7: =IF(D$4>=Assumptions!$B$15,Assumptions!$B$11*Assumptions!$B$14,0) | E7: =IF(E$4>=Assumptions!$B$15,Assumptions!$B$11*Assumptions!$B$14,0) | F7: =IF(F$4>=Assumptions!$B$15,Assumptions!$B$11*Assumptions!$B$14,0) | G7: =IF(G$4>=Assumptions!$B$15,Assumptions!$B$11*Assumptions!$B$14,0) | H7: =IF(H$4>=Assumptions!$B$15,Assumptions!$B$11*Assumptions!$B$14,0) | I7: =IF(I$4>=Assumptions!$B$15,Assumptions!$B$11*Assumptions!$B$14,0) | J7: =IF(J$4>=Assumptions!$B$15,Assumptions!$B$11*Assumptions!$B$14,0) | ... N7: =IF(N$4>=Assumptions!$B$15,Assumptions!$B$11*Assumptions!$B$14,0)
A8: Kar keeps per trip | C8: =C6+C7+Assumptions!$B$16-Assumptions!$B$17-Assumptions!$B$11*Assumptions!$B$18 | D8: =D6+D7+Assumptions!$B$16-Assumptions!$B$17-Assumptions!$B$11*Assumptions!$B$18 | E8: =E6+E7+Assumptions!$B$16-Assumptions!$B$17-Assumptions!$B$11*Assumptions!$B$18 | F8: =F6+F7+Assumptions!$B$16-Assumptions!$B$17-Assumptions!$B$11*Assumptions!$B$18 | G8: =G6+G7+Assumptions!$B$16-Assumptions!$B$17-Assumptions!$B$11*Assumptions!$B$18 | H8: =H6+H7+Assumptions!$B$16-Assumptions!$B$17-Assumptions!$B$11*Assumptions!$B$18 | I8: =I6+I7+Assumptions!$B$16-Assumptions!$B$17-Assumptions!$B$11*Assumptions!$B$18 | J8: =J6+J7+Assumptions!$B$16-Assumptions!$B$17-Assumptions!$B$11*Assumptions!$B$18 | ... N8: =N6+N7+Assumptions!$B$16-Assumptions!$B$17-Assumptions!$B$11*Assumptions!$B$18
A9: Revenue from trips | C9: =C5*C8 | D9: =D5*D8 | E9: =E5*E8 | F9: =F5*F8 | G9: =G5*G8 | H9: =H5*H8 | I9: =I5*I8 | J9: =J5*J8 | ... N9: =N5*N8 | O9: =SUM(B9:N9)
A10: Paying Pro operators | C10: =ROUNDDOWN(Assumptions!B$39*Assumptions!$B$5,0) | D10: =ROUNDDOWN(Assumptions!C$39*Assumptions!$B$5,0) | E10: =ROUNDDOWN(Assumptions!D$39*Assumptions!$B$5,0) | F10: =ROUNDDOWN(Assumptions!E$39*Assumptions!$B$5,0) | G10: =ROUNDDOWN(Assumptions!F$39*Assumptions!$B$5,0) | H10: =ROUNDDOWN(Assumptions!G$39*Assumptions!$B$5,0) | I10: =ROUNDDOWN(Assumptions!H$39*Assumptions!$B$5,0) | J10: =ROUNDDOWN(Assumptions!I$39*Assumptions!$B$5,0) | ... N10: =ROUNDDOWN(Assumptions!M$39*Assumptions!$B$5,0)
A11: Pro subscriptions | C11: =C10*Assumptions!$B$19 | D11: =D10*Assumptions!$B$19 | E11: =E10*Assumptions!$B$19 | F11: =F10*Assumptions!$B$19 | G11: =G10*Assumptions!$B$19 | H11: =H10*Assumptions!$B$19 | I11: =I10*Assumptions!$B$19 | J11: =J10*Assumptions!$B$19 | ... N11: =N10*Assumptions!$B$19 | O11: =SUM(B11:N11)
A12: Key boxes sold | C12: =ROUNDDOWN(Assumptions!B$40*Assumptions!$B$6,0) | D12: =ROUNDDOWN(Assumptions!C$40*Assumptions!$B$6,0) | E12: =ROUNDDOWN(Assumptions!D$40*Assumptions!$B$6,0) | F12: =ROUNDDOWN(Assumptions!E$40*Assumptions!$B$6,0) | G12: =ROUNDDOWN(Assumptions!F$40*Assumptions!$B$6,0) | H12: =ROUNDDOWN(Assumptions!G$40*Assumptions!$B$6,0) | I12: =ROUNDDOWN(Assumptions!H$40*Assumptions!$B$6,0) | J12: =ROUNDDOWN(Assumptions!I$40*Assumptions!$B$6,0) | ... N12: =ROUNDDOWN(Assumptions!M$40*Assumptions!$B$6,0) | O12: =SUM(B12:N12)
A13: GPS trackers sold | C13: =IF(Assumptions!B$41>0,MAX(1,ROUNDDOWN(Assumptions!B$41*Assumptions!$B$6,0)),0) | D13: =IF(Assumptions!C$41>0,MAX(1,ROUNDDOWN(Assumptions!C$41*Assumptions!$B$6,0)),0) | E13: =IF(Assumptions!D$41>0,MAX(1,ROUNDDOWN(Assumptions!D$41*Assumptions!$B$6,0)),0) | F13: =IF(Assumptions!E$41>0,MAX(1,ROUNDDOWN(Assumptions!E$41*Assumptions!$B$6,0)),0) | G13: =IF(Assumptions!F$41>0,MAX(1,ROUNDDOWN(Assumptions!F$41*Assumptions!$B$6,0)),0) | H13: =IF(Assumptions!G$41>0,MAX(1,ROUNDDOWN(Assumptions!G$41*Assumptions!$B$6,0)),0) | I13: =IF(Assumptions!H$41>0,MAX(1,ROUNDDOWN(Assumptions!H$41*Assumptions!$B$6,0)),0) | J13: =IF(Assumptions!I$41>0,MAX(1,ROUNDDOWN(Assumptions!I$41*Assumptions!$B$6,0)),0) | ... N13: =IF(Assumptions!M$41>0,MAX(1,ROUNDDOWN(Assumptions!M$41*Assumptions!$B$6,0)),0) | O13: =SUM(B13:N13)
A14: Active GPS trackers | C14: =SUM($C$13:C13) | D14: =SUM($C$13:D13) | E14: =SUM($C$13:E13) | F14: =SUM($C$13:F13) | G14: =SUM($C$13:G13) | H14: =SUM($C$13:H13) | I14: =SUM($C$13:I13) | J14: =SUM($C$13:J13) | ... N14: =SUM($C$13:N13)
A15: Hardware profit | C15: =C12*Assumptions!$B$20+C13*Assumptions!$B$21+C14*Assumptions!$B$22 | D15: =D12*Assumptions!$B$20+D13*Assumptions!$B$21+D14*Assumptions!$B$22 | E15: =E12*Assumptions!$B$20+E13*Assumptions!$B$21+E14*Assumptions!$B$22 | F15: =F12*Assumptions!$B$20+F13*Assumptions!$B$21+F14*Assumptions!$B$22 | G15: =G12*Assumptions!$B$20+G13*Assumptions!$B$21+G14*Assumptions!$B$22 | H15: =H12*Assumptions!$B$20+H13*Assumptions!$B$21+H14*Assumptions!$B$22 | I15: =I12*Assumptions!$B$20+I13*Assumptions!$B$21+I14*Assumptions!$B$22 | J15: =J12*Assumptions!$B$20+J13*Assumptions!$B$21+J14*Assumptions!$B$22 | ... N15: =N12*Assumptions!$B$20+N13*Assumptions!$B$21+N14*Assumptions!$B$22 | O15: =SUM(B15:N15)
A16: Total money in | B16: 0 | C16: =C9+C11+C15 | D16: =D9+D11+D15 | E16: =E9+E11+E15 | F16: =F9+F11+F15 | G16: =G9+G11+G15 | H16: =H9+H11+H15 | I16: =I9+I11+I15 | J16: =J9+J11+J15 | ... N16: =N9+N11+N15 | O16: =SUM(B16:N16)
A17: Fixed costs | C17: =-IF(Assumptions!$B$7=1,Assumptions!B$43,Assumptions!B$42) | D17: =-IF(Assumptions!$B$7=1,Assumptions!C$43,Assumptions!C$42) | E17: =-IF(Assumptions!$B$7=1,Assumptions!D$43,Assumptions!D$42) | F17: =-IF(Assumptions!$B$7=1,Assumptions!E$43,Assumptions!E$42) | G17: =-IF(Assumptions!$B$7=1,Assumptions!F$43,Assumptions!F$42) | H17: =-IF(Assumptions!$B$7=1,Assumptions!G$43,Assumptions!G$42) | I17: =-IF(Assumptions!$B$7=1,Assumptions!H$43,Assumptions!H$42) | J17: =-IF(Assumptions!$B$7=1,Assumptions!I$43,Assumptions!I$42) | ... N17: =-IF(Assumptions!$B$7=1,Assumptions!M$43,Assumptions!M$42) | O17: =SUM(B17:N17)
A18: One-off costs | B18: =-Assumptions!$B$32 | C18: =IF(AND(C$4=Assumptions!$B$34,Assumptions!$B$8=1),-Assumptions!$B$33,0) | D18: =IF(AND(D$4=Assumptions!$B$34,Assumptions!$B$8=1),-Assumptions!$B$33,0) | E18: =IF(AND(E$4=Assumptions!$B$34,Assumptions!$B$8=1),-Assumptions!$B$33,0) | F18: =IF(AND(F$4=Assumptions!$B$34,Assumptions!$B$8=1),-Assumptions!$B$33,0) | G18: =IF(AND(G$4=Assumptions!$B$34,Assumptions!$B$8=1),-Assumptions!$B$33,0) | H18: =IF(AND(H$4=Assumptions!$B$34,Assumptions!$B$8=1),-Assumptions!$B$33,0) | I18: =IF(AND(I$4=Assumptions!$B$34,Assumptions!$B$8=1),-Assumptions!$B$33,0) | J18: =IF(AND(J$4=Assumptions!$B$34,Assumptions!$B$8=1),-Assumptions!$B$33,0) | ... N18: =IF(AND(N$4=Assumptions!$B$34,Assumptions!$B$8=1),-Assumptions!$B$33,0) | O18: =SUM(B18:N18)
A19: Net cash this month | B19: =B16+B17+B18 | C19: =C16+C17+C18 | D19: =D16+D17+D18 | E19: =E16+E17+E18 | F19: =F16+F17+F18 | G19: =G16+G17+G18 | H19: =H16+H17+H18 | I19: =I16+I17+I18 | ... N19: =N16+N17+N18 | O19: =SUM(B19:N19)
A20: Running cash position | B20: =B19 | C20: =B20+C19 | D20: =C20+D19 | E20: =D20+E19 | F20: =E20+F19 | G20: =F20+G19 | H20: =G20+H19 | I20: =H20+I19 | J20: =I20+J19 | ... N20: =M20+N19 | O20: =N20
A21: Cash position back above zero (month) | C21: =IF(AND(C20>=0,B20<0),C$4,"") | D21: =IF(AND(D20>=0,C20<0),D$4,"") | E21: =IF(AND(E20>=0,D20<0),E$4,"") | F21: =IF(AND(F20>=0,E20<0),F$4,"") | G21: =IF(AND(G20>=0,F20<0),G$4,"") | H21: =IF(AND(H20>=0,G20<0),H$4,"") | I21: =IF(AND(I20>=0,H20<0),I$4,"") | J21: =IF(AND(J20>=0,I20<0),J$4,"") | ... N21: =IF(AND(N20>=0,M20<0),N$4,"")

Sheet Unit Economics
A1: Unit economics
A3: One app trip, after the pilot (RM)
A4: Trip price | B4: =Assumptions!B11
A5: Booking fee (customer pays Kar) | B5: =MAX(Assumptions!B11*Assumptions!B12,Assumptions!B13)
A6: Commission (operator pays Kar) | B6: =Assumptions!B11*Assumptions!B14
A7: Small fees | B7: =Assumptions!B16
A8: Payment gateway | B8: =-Assumptions!B17
A9: Reserve | B9: =-Assumptions!B11*Assumptions!B18
A10: Kar keeps per trip | B10: =SUM(B5:B9)
A11: Operator receives | B11: =B4-B6
A13: What Kar keeps per trip, by average trip price
A14: Trip price (RM) | B14: Kar keeps (RM)
A15: 20 | B15: =MAX(A15*Assumptions!$B$12,Assumptions!$B$13)+A15*Assumptions!$B$14+Assumptions!$B$16-Assumptions!$B$17-A15*Assumptions!$B$18
A16: 40 | B16: =MAX(A16*Assumptions!$B$12,Assumptions!$B$13)+A16*Assumptions!$B$14+Assumptions!$B$16-Assumptions!$B$17-A16*Assumptions!$B$18
A17: 60 | B17: =MAX(A17*Assumptions!$B$12,Assumptions!$B$13)+A17*Assumptions!$B$14+Assumptions!$B$16-Assumptions!$B$17-A17*Assumptions!$B$18
A18: 80 | B18: =MAX(A18*Assumptions!$B$12,Assumptions!$B$13)+A18*Assumptions!$B$14+Assumptions!$B$16-Assumptions!$B$17-A18*Assumptions!$B$18
A19: 100 | B19: =MAX(A19*Assumptions!$B$12,Assumptions!$B$13)+A19*Assumptions!$B$14+Assumptions!$B$16-Assumptions!$B$17-A19*Assumptions!$B$18
A20: 150 | B20: =MAX(A20*Assumptions!$B$12,Assumptions!$B$13)+A20*Assumptions!$B$14+Assumptions!$B$16-Assumptions!$B$17-A20*Assumptions!$B$18
A22: Break-even: app trips per month needed to cover fixed costs
A23: Monthly fixed costs (RM) | B23: =Assumptions!M42
A24: Paying Pro operators | B24: Subscriptions (RM) | C24: App trips needed
A25: 0 | B25: =A25*Assumptions!$B$19 | C25: =IF($B$10>0,ROUNDUP(MAX(0,$B$23-B25)/$B$10,0),"n/a")
A26: 5 | B26: =A26*Assumptions!$B$19 | C26: =IF($B$10>0,ROUNDUP(MAX(0,$B$23-B26)/$B$10,0),"n/a")
A27: 10 | B27: =A27*Assumptions!$B$19 | C27: =IF($B$10>0,ROUNDUP(MAX(0,$B$23-B27)/$B$10,0),"n/a")
A28: 15 | B28: =A28*Assumptions!$B$19 | C28: =IF($B$10>0,ROUNDUP(MAX(0,$B$23-B28)/$B$10,0),"n/a")
A29: 20 | B29: =A29*Assumptions!$B$19 | C29: =IF($B$10>0,ROUNDUP(MAX(0,$B$23-B29)/$B$10,0),"n/a")
A30: 30 | B30: =A30*Assumptions!$B$19 | C30: =IF($B$10>0,ROUNDUP(MAX(0,$B$23-B30)/$B$10,0),"n/a")
A32: Hardware profit is excluded here, which makes this a conservative estimate.

Sheet Capital Plan
A1: Capital plan
A2: ="Scenario: "&Assumptions!B3
A4: Lowest cash position in year 1 (RM) | B4: =-MIN('Cash Flow'!B20:N20)
A5: Month of lowest cash position | B5: =INDEX('Cash Flow'!B4:N4,MATCH(MIN('Cash Flow'!B20:N20),'Cash Flow'!B20:N20,0))
A6: Month cash is back above zero | B6: =IF(COUNT('Cash Flow'!C21:N21)=0,"Not in year 1",MIN('Cash Flow'!C21:N21))
A7: Year 1 profit (RM) | B7: ='Cash Flow'!N20
A9: Recommended starting capital
A10: Cover the lowest cash position | B10: =B4
A11: Claims and goodwill reserve (one bad incident) | B11: 3000
A12: Contingency (~1 month of costs) | B12: =Assumptions!M42
A13: Recommended capital | B13: =SUM(B10:B12)
A15: Where the money can come from
A16: • Own savings or the partnership (Vendor Vision Solutions)
A17: • UTP incubator / entrepreneurship centre
A18: • Cradle CIP grants, MRANTI programmes (check current amounts and when applications open)
A19: • Pre-selling key boxes to operators (cash in before Kar spends it)
A20: • Avoid giving away equity for under RM20k at this stage

Sheet Scenarios
A1: Scenario levers
A2: Pick the active scenario on the Assumptions sheet (cell B3). Blue cells are editable.
A4: Scenario | B4: Trips multiplier | C4: Pro operators multiplier | D4: Hardware multiplier | E4: Lean fixed costs (1 = yes) | F4: Register Sdn Bhd (1 = yes)
A5: Worst | B5: 0.5 | C5: 0.5 | D5: 0.5 | E5: 1 | F5: 0
A6: Base | B6: 1 | C6: 1 | D6: 1 | E6: 0 | F6: 1
A7: Best | B7: 1.5 | C7: 1.5 | D7: 1 | E7: 0 | F7: 1
A9: Worst = half the trips, operators and hardware sales, lean costs (RM900/month to month 6, RM1,800 after), no Sdn Bhd. Best = 1.5x trips and operators. Source: Kar planning estimates (Oct 2026), not real data yet.
